Workbook
Name В11: Накладная!$A$12
Name В22: Накладная!$A$62
Name Значение: #REF!
Name Значение: #REF!
Name Значение: #REF!
Name Обвязочныйбрус: #REF!
Name Обвязочныйбрус: #REF!
Name Обвязочныйбрус: #REF!

Sheet Прайс
A1: Наименование работы | B1: Ед.измер. | C1: Характеристика | D1: Себ-ть,руб. | E1: Розница,руб
A2: Фундаменты
A3: Ленточный фундамет
A4: Выемка грунта вручную | B4: м3 | D4: 1000 | E4: 1200
A5: Выемка грунта механизировано | B5: м/ч | C5: мин 4 часа | D5: 1250 | E5: 1500
A6: Кирпич красный м 200 | B6: шт | D6: 30 | E6: 36
A7: Кирпич красный м 150 | B7: шт | D7: 20 | E7: 24
A8: Кирпич белый | B8: шт | D8: 16 | E8: 19.2
A9: Пленка (150 мк) | B9: м2 | D9: 15 | E9: 18
A10: Песок | B10: м3 | C10: 1,67т | D10: 667 | E10: 800.4
A11: Щебень(гранит 20 на 40) | B11: м3 | C11: 1,35т | D11: 1553 | E11: 1863.6
A12: Щебень (известняк 20 на 40) | B12: м3 | C12: 1,3т | D12: 476 | E12: 571.2
A13: Бетон | B13: м3 | C13: м 200 | D13: 3500 | E13: 4200
A14: Арматура( 8) | B14: п.м | D14: 15 | E14: 18
A15: Арматура( 10) | B15: п.м | D15: 19 | E15: 22.8
A16: Арматура (12) | B16: п.м. | D16: 25 | E16: 30
A17: Арматура пластик( 6) | B17: п.м. | D17: 10 | E17: 12
A18: Арматура пластик(8) | B18: п.м | D18: 15 | E18: 18
A19: Арматура пластик(10) | B19: п.м | D19: 22 | E19: 26.4
A20: Арматура пластик(12) | B20: п.м | D20: 30 | E20: 36
A21: Вязальная пров-ка | B21: кг | C21: min 3 кг | D21: 90 | E21: 108
A22: Опалубка | B22: м3 | C22: доски 2 сорт | D22: 4000 | E22: 4800
A23: Опалубка 1250Х2500х12 | B23: 1 шт | C23: OSB (3.125) | D23: 700 | E23: 840
A24: Аренда мотобура(для свай) | B24: сутки | D24: 5000 | E24: 6000
A25: Аренда буромашины(для свай) | B25: час | C25: min 4 час | D25: 1600 | E25: 1920
A26: Блочный фундамент | E26: 0
A27: Блок | B27: шт | D27: 41 | E27: 60
A28: Смесь М 150 | B28: меш | C28: 25 кг | D28: 90 | E28: 108
A29: Рубероид | B29: шт | C29: 1000 Х15000 | D29: 350 | E29: 420
A30: Свайно-винтовой | F30: Цена работы
A31: Керамзитобетонный блок | D31: 41
A32: Свая 2000 | B32: шт | C32: 1,5 меш.смеси | D32: 1400 | E32: 1680 | F32: 800
A33: Свая 2500 | B33: шт | C33: 2 меш смеси | D33: 1500 | E33: 1800 | F33: 800
A34: Свая 3000 | B34: шт | C34: 2,5 меш.смеси | D34: 1700 | E34: 2040 | F34: 1000
A35: Увеличение длины сваи | B35: 1 м.п. | D35: 250 | E35: 300 | F35: 100
A36: Укосины по сваям с грунтом | B36: 1 м.п. | D36: 250 | E36: 300 | F36: 150
A37: Обвязка швеллером 16 с грунтом | B37: 1 м.п. | D37: 600 | E37: 720 | F37: 300
A38: Пиломатериал( 6 м)
A39: 200Х200 | B39: шт | C39: 6500 | D39: =C39*0.2*0.2*6 -> 1560 | E39: =D39*1.2 -> 1872
A40: 150Х200 | B40: шт | C40: 6500 | D40: =C40*0.2*0.15*6 -> 1170 | E40: =D40*1.2 -> 1404
...

Sheet Просчет
A1: Сумма договора | B1: 0 | D1: Номер договора | E1: №
A4: Наименование | B4: Кол-во | C4: Ед. изм. | D4: Цена единицы | E4: Итого: | F4: сто-ть мат-ла | G4: Общий вес, кг | H4: Примечание
A5: Фундамент
A6: Блоки | C6: шт | G6: =F6*B6 -> 0
A7: Свая 2000 | C7: шт | G7: =F7*B7 -> 0
A8: Свая 2500 | C8: шт | G8: =F8*B8 -> 0
A9: Свайный фундамент (забивные сваи) | C9: шт | G9: =F9*B9 -> 0
A10: Смесь М150 | B10: =ROUNDUP(B6/8+B7*1.2+B8*1.5+B9*1.7,0) -> 0 | C10: шт | F10: 0 | G10: =F10*B10 -> 0
A11: Рубероид | B11: 1 | C11: шт | F11: 438 | G11: =B11*F11 -> 438
A12: Антисептик 3TREE BIO 10кг | B12: 2 | C12: шт | F12: 460 | G12: =B12*F12 -> 920
A13: Глухарь 8*100 | B13: =ROUNDUP(B7*2+B8*2+B9*2,0) -> 0 | C13: шт | F13: 0 | G13: =F13*B13 -> 0 | H13: глухарь+шайба для крепления в сваях
A14: Шайба М8 ув | B14: =ROUNDUP(B7*2+B8*2+B9*2,0) -> 0 | C14: шт | F14: 0 | G14: =F14*B14 -> 0
A15: Шпилька 10*1000 | C15: шт | F15: 0 | G15: =F15*B15 -> 0 | H15: Шпилька+гайка+шайба = анкерные болты= для крепления в буронабивных фундаментах
A16: Шайба М6 ув | B16: =B15*4*2 -> 0 | C16: шт | F16: 0 | G16: =F16*B16 -> 0
A17: Гайка М10 | B17: =B15*2*4 -> 0 | C17: шт | F17: 0 | G17: =F17*B17 -> 0
A18: Цанга | B18: =B17 -> 0 | C18: шт
A19: Буронабивной фундамент | C19: шт | G19: =F19*B19 -> 0
A20: Буронабивной фундамент с монолитной плитой | C20: шт | G20: =F20*B20 -> 0
A21: Ж/б лента | C21: шт | G21: =F21*B21 -> 0
A22: Фундаментная плита | C22: шт | G22: =F22*B22 -> 0
A23: Сетка от грызунов 1*10м | C23: шт | F23: 219 | G23: =F23*B23 -> 0
A24: Цоколь
A25: HAUBERK ТЕХНОНИКОЛЬ Терракотовый кирпич | C25: м2 | G25: =F25*B25 -> 0
A26: Пенополистерол 1180х580х50мм | B26: =(B25*0.05)/0.036 -> 0 | C26: шт | G26: =F26*B26 -> 0
A27: ЦСП 10 | B27: =B25/3.375 -> 0 | C27: шт | G27: =F27*B27 -> 0
A28: Профиль 20*40 | B28: =B25/0.4*2 -> 0 | C28: пог. М | G28: =F28*B28 -> 0 | H28: если винтовые сваи
A29: 40*50*3 | B29: =B25/0.4*2/3 -> 0 | C29: шт | G29: =F29*B29 -> 0 | H29: если забивные сваи
A30: Отливы 10 (на фундамент, цвет - вишня) | B30: =B25/0.4/1.9 -> 0 | C30: шт | G30: =F30*B30 -> 0
A31: Брус для обвязки
A32: 50*100*6 обвязка | C32: шт | E32: =0.05*0.1*6*B32 -> 0 | F32: 11500 | G32: =F32*E32 -> 0
A33: 50*150*6 обвязка | C33: шт | E33: =0.05*0.15*6*B33 -> 0 | F33: 11500 | G33: =F33*E33 -> 0
A34: 50*200*6 обвязка | C34: шт | E34: =0.05*0.2*6*B34 -> 0 | F34: 11500 | G34: =F34*E34 -> 0
A35: 100*100*6 обвязка | C35: шт | E35: =0.1*0.1*6*B35 -> 0 | F35: 11500 | G35: =F35*E35 -> 0
A36: 100*150*6 обвязка | C36: шт | E36: =0.1*0.15*6*B36 -> 0 | F36: 11500 | G36: =F36*E36 -> 0
A37: 100*200*6 обвязка | C37: шт | E37: =0.1*0.2*6*B37 -> 0 | F37: 11500 | G37: =F37*E37 -> 0
A38: 150*150*6 обвязка | C38: шт | E38: =0.15*0.15*6*B38 -> 0 | F38: 11500 | G38: =F38*E38 -> 0
A39: 150*200*6 обвязка | C39: шт | E39: =0.15*0.2*6*B39 -> 0 | F39: 11500 | G39: =F39*E39 -> 0
A40: 200*200*6 обвязка | C40: шт | E40: =0.2*0.2*6*B40 -> 0 | F40: 11500 | G40: =F40*E40 -> 0
A41: 50*100*6 сухой обвязка | C41: шт | E41: =0.05*0.1*6*B41 -> 0 | F41: 13500 | G41: =F41*E41 -> 0
A42: 50*150*6 сухой обвязка | C42: шт | E42: =0.05*0.15*6*B42 -> 0 | F42: 13500 | G42: =F42*E42 -> 0
...

Sheet Накладная
A1: Накладная № | B1: =Просчет!E1 -> № | C1: от "_ _" _______ 2021 г.
A3: Адрес доставки:
A4: Телефон заказчика:
A5: Имя заказчика:
A6: Телефон бригадира:
A7: Имя бригадира:
A8: Доставка, № А/М:
A11: Наименование | B11: =Просчет!B4 -> Кол-во | C11: =Просчет!C4 -> Ед. изм. | D11: Заезд | E11: Довозка №1 | F11: Довозка №2 | G11: Довозка №3
A12: Фундамент | B12: - | C12: -
A13: =Просчет!A6 -> Блоки | B13: =Просчет!B6 -> 0 | C13: =Просчет!C6 -> шт
A14: =Просчет!A7 -> Свая 2000 | B14: =Просчет!B7 -> 0 | C14: =Просчет!C7 -> шт
A15: =Просчет!A8 -> Свая 2500 | B15: =Просчет!B8 -> 0 | C15: =Просчет!C8 -> шт
A16: =Просчет!A9 -> Свайный фундамент (забивные сваи) | B16: =Просчет!B9 -> 0 | C16: =Просчет!C9 -> шт
A17: =Просчет!A10 -> Смесь М150 | B17: =Просчет!B10 -> 0 | C17: =Просчет!C10 -> шт
A18: =Просчет!A11 -> Рубероид | B18: =Просчет!B11 -> 1 | C18: =Просчет!C11 -> шт
A19: =Просчет!A12 -> Антисептик 3TREE BIO 10кг | B19: =Просчет!B12 -> 2 | C19: =Просчет!C12 -> шт
A20: =Просчет!A13 -> Глухарь 8*100 | B20: =Просчет!B13 -> 0 | C20: =Просчет!C13 -> шт
A21: =Просчет!A14 -> Шайба М8 ув | B21: =Просчет!B14 -> 0 | C21: =Просчет!C14 -> шт
A22: =Просчет!A15 -> Шпилька 10*1000 | B22: =Просчет!B15 -> 0 | C22: =Просчет!C15 -> шт
A23: =Просчет!A16 -> Шайба М6 ув | B23: =Просчет!B16 -> 0 | C23: =Просчет!C16 -> шт
A24: =Просчет!A17 -> Гайка М10 | B24: =Просчет!B17 -> 0 | C24: =Просчет!C17 -> шт
... A30: =Просчет!A23 -> Сетка от грызунов 1*10м | B30: =Просчет!B23 -> 0 | C30: =Просчет!C23 -> шт
A31: =Просчет!A24 -> Цоколь | B31: - | C31: -
A32: =Просчет!A25 -> HAUBERK ТЕХНОНИКОЛЬ Терракотовый кирпич | B32: =Просчет!B25 -> 0 | C32: =Просчет!C25 -> м2
A33: =Просчет!A26 -> Пенополистерол 1180х580х50мм | B33: =Просчет!B26 -> 0 | C33: =Просчет!C26 -> шт
A34: =Просчет!A27 -> ЦСП 10 | B34: =Просчет!B27 -> 0 | C34: =Просчет!C27 -> шт
A35: =Просчет!A28 -> Профиль 20*40 | B35: =Просчет!B28 -> 0 | C35: =Просчет!C28 -> пог. М
A36: =Просчет!A29 -> 40*50*3 | B36: =Просчет!B29 -> 0 | C36: =Просчет!C29 -> шт
A37: =Просчет!A30 -> Отливы 10 (на фундамент, цвет - вишня) | B37: =Просчет!B30 -> 0 | C37: =Просчет!C30 -> шт
A38: =Просчет!A31 -> Брус для обвязки | B38: - | C38: -
A39: =Просчет!A32 -> 50*100*6 обвязка | B39: =Просчет!B32 -> 0 | C39: =Просчет!C32 -> шт
A40: =Просчет!A33 -> 50*150*6 обвязка | B40: =Просчет!B33 -> 0 | C40: =Просчет!C33 -> шт
A41: =Просчет!A34 -> 50*200*6 обвязка | B41: =Просчет!B34 -> 0 | C41: =Просчет!C34 -> шт
A42: =Просчет!A35 -> 100*100*6 обвязка | B42: =Просчет!B35 -> 0 | C42: =Просчет!C35 -> шт
A43: =Просчет!A36 -> 100*150*6 обвязка | B43: =Просчет!B36 -> 0 | C43: =Просчет!C36 -> шт
A44: =Просчет!A37 -> 100*200*6 обвязка | B44: =Просчет!B37 -> 0 | C44: =Просчет!C37 -> шт
A45: =Просчет!A38 -> 150*150*6 обвязка | B45: =Просчет!B38 -> 0 | C45: =Просчет!C38 -> шт
A46: =Просчет!A39 -> 150*200*6 обвязка | B46: =Просчет!B39 -> 0 | C46: =Просчет!C39 -> шт
A47: =Просчет!A40 -> 200*200*6 обвязка | B47: =Просчет!B40 -> 0 | C47: =Просчет!C40 -> шт
A48: =Просчет!A41 -> 50*100*6 сухой обвязка | B48: =Просчет!B41 -> 0 | C48: =Просчет!C41 -> шт
...

Sheet Мини-смета для клиента
A1: Смета для Заказчика | I1: Смета в бухгалтерию | N1: Выбери % - | O1: 15
F3: Приложение № 3 | N3: Приложение № 3
F4: =_xlfn.TEXTJOIN(,,"к Договору ",Просчет!E1) -> к Договору № | N4: =F4 -> к Договору №
F5: от "_____"______________20____г. | N5: =F5 -> от "_____"______________20____г. | R5: Жилой дом
R6: Дача
A7: СВОДНЫЙ СМЕТНЫЙ РАСЧЕТ | I7: СВОДНЫЙ СМЕТНЫЙ РАСЧЕТ | R7: Баня
R8: Гараж
A9: Дата: | E9: 11.12.2020 | I9: Дата: | M9: =E9 -> 11.12.2020 | R9: Сарай
A10: Объект: | E10: Жилой дом | I10: Объект: | M10: =E10 -> Жилой дом | R10: Беседка
A11: Сметная стоимость: | E11: =_xlfn.TEXTJOIN(,,G37," руб.") -> 609099,426864 руб. | I11: Сметная стоимость: | M11: =_xlfn.TEXTJOIN(,,O37," руб.") -> 517734,5128344 руб.
A14: Наименование работ и ресурсов | C14: Кол-во | D14: Ед.изм | E14: Сметная стоимость, руб. | G14: Общая сметная стоимость, руб. | I14: Наименование работ и ресурсов | K14: Кол-во | L14: Ед.изм | M14: Сметная стоимость, руб. | O14: Общая сметная стоимость, руб. | Q14: ПРИМЕЧАНИЕ!!! | R14: % Для бухгалтерии
E15: Материалы | F15: Оплата труда | M15: Материалы | N15: Оплата труда | Q15: В смете не учтены следующие цены (нужно добавить вручную): | R15: 10
A16: 1.Фундамент | I16: 1.Фундамент | R16: 11
A17: 1.1 Устройство фундамента (включая цоколь) | C17: =IF(E17>0,1,0) -> 0 | D17: комплект | E17: 0 | F17: =E17/1.25*0.55 -> 0 | G17: =E17+F17 -> 0 | I17: 1.1 Устройство фундамента (включая цоколь) | K17: =C17 -> 0 | L17: =D17 -> комплект | M17: =E17*((100-O1)*0.01) -> 0 | N17: =F17*((100-O1)*0.01) -> 0 | O17: =M17+N17 -> 0 | Q17: Фундамент, цоколь | R17: 12
A18: 2.Пиломатериал | I18: 2.Пиломатериал | R18: 13
A19: 2.1 Устройство каркаса/сборка сруба | C19: =IF(E19>0,1,0) -> 1 | D19: комплект | E19: =SUM(Просчет!G32:G54)+SUM(Просчет!G56:G71)+SUM(Просчет!G73:G88)+SUM(Просчет!G90:G99)+SUM(Просчет!G101:G106)+SUM(Просчет!G108:G116)+Просчет!G12 -> 62578.626 | F19: =E19/1.25*0.55 -> 27534.595 | G19: =E19+F19 -> 90113.221 | I19: 2.1 Устройство каркаса/сборка сруба | K19: =C19 -> 1 | L19: =D19 -> комплект | M19: =E19*((100-O1)*0.01) -> 53191.832 | N19: =F19*((100-O1)*0.01) -> 23404.406 | O19: =M19+N19 -> 76596.238 | R19: 14
A20: 3.Отделочные материалы | I20: 3.Отделочные материалы | R20: 15
A21: 3.1 Устройство отделки (включая элементы бани) | C21: =IF(E21>0,1,0) -> 1 | D21: комплект | E21: =SUM(Просчет!G118:G149)+SUM(Просчет!G168:G174)+SUM(Просчет!G265:G289)+SUM(Просчет!G291:G299) -> 119250 | F21: =E21/1.25*0.55 -> 52470 | G21: =E21+F21 -> 171720 | I21: 3.1 Устройство отделки (включая элементы бани) | K21: =C21 -> 1 | L21: =D21 -> комплект | M21: =E21*((100-O1)*0.01) -> 101362.5 | N21: =F21*((100-O1)*0.01) -> 44599.5 | O21: =M21+N21 -> 145962 | Q21: Монтаж материалов заказчика, позиции из пункта "Прочее"
A22: 4.Окна и двери | I22: 4.Окна и двери
A23: 4.1 Устройство окон и дверей | C23: =IF(E23>0,1,0) -> 0 | D23: комплект | E23: =SUM(Просчет!G151:G166) -> 0 | F23: =E23/1.25*0.55 -> 0 | G23: =E23+F23 -> 0 | I23: 4.1 Устройство окон и дверей | K23: =C23 -> 0 | L23: =D23 -> комплект | M23: =E23*((100-O1)*0.01) -> 0 | N23: =F23*((100-O1)*0.01) -> 0 | O23: =M23+N23 -> 0 | Q23: Окна, двери мдф и двери браво
A24: 5.Крепеж | I24: 5.Крепеж
A25: 5.1 Устройство крепежа | C25: =IF(E25>0,1,0) -> 1 | D25: комплект | E25: =SUM(Просчет!G176:G225)*1.25+Просчет!G11+Просчет!G23 -> 39002.688 | F25: =E25/1.25*0.55 -> 17161.183 | G25: =E25+F25 -> 56163.87 | I25: 5.1 Устройство крепежа | K25: =C25 -> 1 | L25: =D25 -> комплект | M25: =E25*((100-O1)*0.01) -> 33152.284 | N25: =F25*((100-O1)*0.01) -> 14587.005 | O25: =M25+N25 -> 47739.289
A26: 6.Кровля | I26: 6.Кровля
A27: 6.1 Устройство кровли | C27: =IF(E27>0,1,0) -> 1 | D27: комплект | E27: =SUM(Просчет!G227:G236) -> 139432 | F27: =E27/1.25*0.55 -> 61350.08 | G27: =E27+F27 -> 200782.08 | I27: 6.1 Устройство кровли | K27: =C27 -> 1 | L27: =D27 -> комплект | M27: =E27*((100-O1)*0.01) -> 118517.2 | N27: =F27*((100-O1)*0.01) -> 52147.568 | O27: =M27+N27 -> 170664.77
A28: 7.Пленки и утеплители | I28: 7.Пленки и утеплители
A29: 7.1 Устройство пленок и утепления | C29: =IF(E29>0,1,0) -> 1 | D29: комплект | E29: =SUM(Просчет!G238:G253) -> 60209.9 | F29: =E29/1.25*0.55 -> 26492.356 | G29: =E29+F29 -> 86702.256 | I29: 7.1 Устройство пленок и утепления | K29: =C29 -> 1 | L29: =D29 -> комплект | M29: =E29*((100-O1)*0.01) -> 51178.415 | N29: =F29*((100-O1)*0.01) -> 22518.503 | O29: =M29+N29 -> 73696.918
A30: 8.Погонажные изделия | I30: 8.Погонажные изделия
A31: 8.1 Устройство погонажа | C31: =IF(E31>0,1,0) -> 1 | D31: комплект | E31: =SUM(Просчет!G255:G263)*1.25 -> 2512.5 | F31: =E31/1.25*0.55 -> 1105.5 | G31: =E31+F31 -> 3618 | I31: 8.1 Устройство погонажа | K31: =C31 -> 1 | L31: =D31 -> комплект | M31: =E31*((100-O1)*0.01) -> 2135.625 | N31: =F31*((100-O1)*0.01) -> 939.675 | O31: =M31+N31 -> 3075.3
A32: 9.Покраска | I32: 9.Покраска
A33: 9.1 Устройство покраски | C33: =IF(E33>0,1,0) -> 0 | D33: комплект | E33: 0 | F33: =E33/1.25*0.55 -> 0 | G33: =E33+F33 -> 0 | I33: 9.1 Устройство покраски | K33: =C33 -> 0 | L33: =D33 -> комплект | M33: =E33*((100-O1)*0.01) -> 0 | N33: =F33*((100-O1)*0.01) -> 0 | O33: =M33+N33 -> 0 | Q33: Покраска
A34: 10.Прочие расходы | I34: 10.Прочие расходы
A35: 10.1 Устройство прочих расходов и доставка | C35: =IF(F35>0,1,0) -> 0 | D35: комплект | E35: 0 | F35: 0 | G35: =E35+F35 -> 0 | I35: 10.1 Устройство прочих расходов и доставка | K35: =C35 -> 0 | L35: =D35 -> комплект | M35: =E35*((100-O1)*0.01) -> 0 | N35: =F35*((100-O1)*0.01) -> 0 | O35: =M35+N35 -> 0 | Q35: Разработка эскизного проекта, Разгрузка и погрузка материала,
Q36: такелажные работы, Аренда бытовки, Устройство лесов, Доставка
A37: Итого по смете,руб.: | G37: =SUM(G16:G35) -> 609099.43 | I37: Итого по смете,руб.: | O37: =SUM(O16:O35) -> 517734.51 | P37: = | Q37: =G37*((100-O1)*0.01) -> 517734.51
A41: Заказчик:________________/___________________/ | I41: Заказчик:________________/___________________/
A43: Подрядчик:________________/_________________/ | I43: Подрядчик:________________/_________________/

Sheet Маленькая смета для клиента
A1: Приложение №3 к договору строительного подряда №00/00 от 00.00.2020 г.
A3: № | B3: Работа | C3: Материал | D3: Кол-во | E3: Ед. изм. | F3: Стоимость ед. материал | G3: Стоимость ед. работа | H3: Итого
A4: 1 | B4: Устройство фундамента
B5: Устройство фундамента | C5: ? | D5: =IF(C5>0,1,0) -> 1 | E5: компл. | H5: =(F5+G5)*D5 -> 0
B6: Геология | D6: =IF(Просчет!B9>0,1,0) -> 0 | E6: компл. | G6: =F6/1.25*0.55 -> 0 | H6: =(F6+G6)*D6 -> 0
B7: Устройство цоколя | C7: Материал предоставляет Заказчик | D7: 0 | E7: компл. | F7: 0 | G7: =F7/1.25*0.55 -> 0 | H7: =(F7+G7)*D7 -> 0
B8: Устройство цоколя | C8: =Просчет!A25 -> HAUBERK ТЕХНОНИКОЛЬ Терракотовый кирпич | D8: =Просчет!B25 -> 0 | E8: =Просчет!C25 -> м2 | G8: =F8/1.25*0.55 -> 0 | H8: =(F8+G8)*D8 -> 0
A9: =A4+1 -> 2 | B9: Устройство каркаса и стропильной системы дома
B10: Устройство каркаса и стропильной системы дома | C10: Брус естественной влажности | D10: =SUM(Просчет!E32:E40)+SUM(Просчет!E56:E71) -> 0 | E10: м3 | F10: 11500 | G10: =F10/1.25*0.55 -> 5060 | H10: =(F10+G10)*D10 -> 0
B11: Устройство каркаса и стропильной системы дома | C11: Брус сухой нестроганый | D11: =SUM(Просчет!E41:E49)+SUM(Просчет!E73:E88) -> 0 | E11: м3 | F11: 13500 | G11: =F11/1.25*0.55 -> 5940 | H11: =(F11+G11)*D11 -> 0
B12: Устройство каркаса и стропильной системы дома | C12: Брус сухой строганый | D12: =SUM(Просчет!E50:E54)+SUM(Просчет!E90:E99) -> 3.7368 | E12: м3 | F12: 16500 | G12: =F12/1.25*0.55 -> 7260 | H12: =(F12+G12)*D12 -> 88786.368
B13: Сборка в лапу профилированного бруса | C13: Профрофилированный брус (сборка в лапу) | D13: =SUM(Просчет!E101:E103) -> 0 | E13: м3 | F13: 14125 | G13: =F13/1.25*0.55 -> 6215 | H13: =(F13+G13)*D13 -> 0
B14: Сборка в лапу профилированного бруса | C14: Профрофилированный брус, сухой (сборка в лапу) | D14: =SUM(Просчет!E104:E106) -> 0 | E14: м3 | F14: 17875 | G14: =F14/1.25*0.55 -> 7865 | H14: =(F14+G14)*D14 -> 0
B15: Сборка в чашу профилированного бруса | C15: Профрофилированный брус, сухой (сборка в чашу) | D15: =SUM(Просчет!B108:B110) -> 0 | E15: м3 | F15: 17750 | G15: =F15/1.25*0.55 -> 7810 | H15: =(F15+G15)*D15 -> 0 | J15: сборка в чашу из сырого = 14375р/м3
B16: Сборка оцилиндрованного бревна | C16: Оцилиндрованное бревно ф18 | D16: =Просчет!B111 -> 0 | E16: м3 | F16: 11000 | G16: =F16/1.25*0.55 -> 4840 | H16: =(F16+G16)*D16 -> 0
B17: Сборка оцилиндрованного бревна | C17: Оцилиндрованное бревно ф20 | D17: =Просчет!B112 -> 0 | E17: м3 | F17: 11000 | G17: =F17/1.25*0.55 -> 4840 | H17: =(F17+G17)*D17 -> 0
B18: Сборка оцилиндрованного бревна | C18: Оцилиндрованное бревно ф22 | D18: =Просчет!B113 -> 0 | E18: м3 | F18: 11000 | G18: =F18/1.25*0.55 -> 4840 | H18: =(F18+G18)*D18 -> 0
B19: Сборка оцилиндрованного бревна | C19: Оцилиндрованное бревно ф24 | D19: =Просчет!B114 -> 0 | E19: м3 | F19: 11000 | G19: =F19/1.25*0.55 -> 4840 | H19: =(F19+G19)*D19 -> 0
B20: Сборка оцилиндрованного бревна | C20: Оцилиндрованное бревно ф24 (финский профиль) | D20: =Просчет!B115 -> 0 | E20: м3 | G20: =F20/1.25*0.55 -> 0 | H20: =(F20+G20)*D20 -> 0
B21: Сборка оцилиндрованного бревна | C21: Оцилиндрованное бревно ф26 | D21: =Просчет!B116 -> 0 | E21: м3 | G21: =F21/1.25*0.55 -> 0 | H21: =(F21+G21)*D21 -> 0
B22: Антисептирование пиломатериала | C22: =Просчет!A12 -> Антисептик 3TREE BIO 10кг | D22: =IF(Просчет!B12>0,1,0) -> 1 | E22: компл. | F22: =Просчет!G12 -> 920 | G22: =F22/1.25*0.55 -> 404.8 | H22: =(F22+G22)*D22 -> 1324.8
A23: =A9+1 -> 3 | B23: Устройство кровли
B24: Устройство покрытия кровли | C24: Оцинкованный профнастил | D24: =Просчет!B227 -> 0 | E24: м2 | F24: 488 | G24: =F24/1.25*0.55 -> 214.72 | H24: =(F24+G24)*D24 -> 0
B25: Устройство покрытия кровли | C25: Крашенный профнастил | D25: =Просчет!B228 -> 164 | E25: м2 | F25: 713 | G25: =F25/1.25*0.55 -> 313.72 | H25: =(F25+G25)*D25 -> 168382.08
B26: Устройство покрытия кровли | C26: Металлочерепица | D26: =Просчет!B229 -> 0 | E26: м2 | F26: 750 | G26: =F26/1.25*0.55 -> 330 | H26: =(F26+G26)*D26 -> 0
B27: Устройство покрытия кровли | C27: Гибкая черепица | D27: =Просчет!B230 -> 0 | E27: м2 | G27: =F27/1.25*0.55 -> 0 | H27: =(F27+G27)*D27 -> 0
B28: Устройство водосточной системы | C28: Водосточная система ПВХ на металлических кронштейнах | D28: =IF(Просчет!B231>0,1,0) -> 1 | E28: компл. | G28: =F28/1.25*0.55 -> 0 | H28: =(F28+G28)*D28 -> 0
B29: Устройство водосточной системы | C29: Водосточная система ПВХ на металлических кронштейнах | D29: =IF(Просчет!B232>0,1,0) -> 0 | E29: компл. | G29: =F29/1.25*0.55 -> 0 | H29: =(F29+G29)*D29 -> 0
B30: Устройство снегозадержателя | C30: Снегозадержатель | D30: =IF(Просчет!B233>0,1,0) -> 0 | E30: компл. | G30: =F30/1.25*0.55 -> 0 | H30: =(F30+G30)*D30 -> 0
B31: Устройство подшива карнизов, потолков крыльца, террасы и навеса | C31: Сайдинг | D31: =Просчет!B234 -> 0 | E31: м2 | G31: =F31/1.25*0.55 -> 0 | H31: =(F31+G31)*D31 -> 0
B32: Устройство подшива карнизов, потолков крыльца, террасы и навеса | C32: Вагонка 90х12,5 - 6м, Сорт АВ | D32: =Просчет!B134 -> 0 | E32: м2 | F32: 275 | G32: =F32/1.25*0.55 -> 121 | H32: =(F32+G32)*D32 -> 0
B33: Устройство подшива карнизов, потолков крыльца, террасы и навеса | C33: Вагонка 90х12,5 - 6м, Сорт Эконом | D33: =Просчет!B136 -> 0 | E33: м2 | F33: 194 | G33: =F33/1.25*0.55 -> 85.36 | H33: =(F33+G33)*D33 -> 0
B34: Устройство подшива карнизов, потолков крыльца, террасы и навеса | C34: Рау-хаус 135х16- 6м, Сорт АВ | D34: =Просчет!B137 -> 99 | E34: м2 | F34: 450 | G34: =F34/1.25*0.55 -> 198 | H34: =(F34+G34)*D34 -> 64152
B35: Устройство подшива карнизов, потолков крыльца, террасы и навеса | C35: Софит перфорированный 50/50 | D35: =Просчет!B235 -> 0 | E35: м2 | G35: =F35/1.25*0.55 -> 0 | H35: =(F35+G35)*D35 -> 0
B36: Устройство вентиляционных решеток | C36: Вентиляционная решетка | D36: =Просчет!B236 -> 0 | E36: шт | F36: 500 | G36: =F36/1.25*0.55 -> 220 | H36: =(F36+G36)*D36 -> 0
A37: =A23+1 -> 4 | B37: Паро/гидроизоляция
B38: Гидроизоляция | C38: Спанизол А | D38: =Просчет!B243+Просчет!B244*0.5 -> 0 | E38: шт | F38: 938 | G38: =F38/1.25*0.55 -> 412.72 | H38: =(F38+G38)*D38 -> 0
B39: Пароизоляция | C39: Фольгированная пароизоляция | D39: =Просчет!B278 -> 0 | E39: шт | F39: 900 | G39: =F39/1.25*0.55 -> 396 | H39: =(F39+G39)*D39 -> 0
B40: Пароизоляция | C40: Спанизол В | D40: =Просчет!B245+Просчет!B246*0.5 -> 0 | E40: шт | F40: 788 | G40: =F40/1.25*0.55 -> 346.72 | H40: =(F40+G40)*D40 -> 0
B41: Гидроизоляция кровли | C41: Спанизол АМ | D41: =Просчет!B247+Просчет!B248*0.5 -> 0 | E41: шт | F41: 2313 | G41: =F41/1.25*0.55 -> 1017.72 | H41: =(F41+G41)*D41 -> 0
...

Sheet Смета в налоговую
A1: СОГЛАСОВАНО: | F1: УТВЕРЖДАЮ:
A4: __________ | F4: __________
A5: "____" __________ 20__ г. | F5: "____" __________ 20__ г.
A6: Приложение №3 к договору 00/00 от 00 мая 0000 года на строительство дома
A7: (наименование стройки)
A9: СМЕТНЫЙ РАСЧЕТ
A10: (локальная смета)
A12: на Строительство дома по адресу: 00000
A16: № | B16: Работа | C16: Материал | D16: Кол-во | E16: Ед. изм. | F16: Стоимость ед. материал | G16: Стоимость ед. работа | H16: Итого
A17: 1 | B17: Устройство фундамента
B18: Устройство фундамента | C18: =Просчет!H54 -> 0 | D18: =IF(C18>0,1,0) -> 0 | E18: компл. | H18: =(F18+G18)*D18 -> 0
B19: Устройство сетки от грызунов | C19: =Просчет!A23 -> Сетка от грызунов 1*10м | D19: =Просчет!B23 -> 0 | E19: компл. | F19: 219 | G19: =F19/1.25*0.55 -> 96.36 | H19: =(F19+G19)*D19 -> 0
B20: Геология | D20: =IF(Просчет!B9>0,1,0) -> 0 | E20: компл. | G20: =F20/1.25*0.55 -> 0 | H20: =(F20+G20)*D20 -> 0
B21: Устройство цоколя | C21: Материал предоставляет Заказчик | D21: 0 | E21: компл. | F21: 0 | G21: =F21/1.25*0.55 -> 0 | H21: =(F21+G21)*D21 -> 0
B22: Устройство цоколя | C22: =Просчет!A25 -> HAUBERK ТЕХНОНИКОЛЬ Терракотовый кирпич | D22: =Просчет!B25 -> 0 | E22: =Просчет!C25 -> м2 | G22: =F22/1.25*0.55 -> 0 | H22: =(F22+G22)*D22 -> 0
A23: =A17+1 -> 2 | B23: Устройство каркаса и стропильной системы дома
B24: =_xlfn.TEXTJOIN(", ",,IF(Просчет!I56='Смета в налоговую'!C24,Просчет!H56,""),IF(Просчет!I57='Смета в налоговую'!C24,Просчет!H57,""),IF(Просчет!I58='Смета в налоговую'!C24,Просчет!H58,""),IF(Просчет!I59='Смета в налоговую'!C24,Просчет!H59,""),IF(Просчет!I60='Смета в налоговую'!C24,Просчет!H60,""),IF(Просчет!I61='Смета в налоговую'!C24,Просчет!H61,""),IF(Просчет!I62='Смета в налоговую'!C24,Просчет!H62,""),IF(Просчет!I63='Смета в налоговую'!C24,Просчет!H63,""),IF(Просчет!I64='Смета в налоговую'!C24,Просчет!H64,""),IF(Просчет!I65='Смета в налоговую'!C24,Просчет!H65,""),IF(Просчет!I66='Смета в налоговую'!C24,Просчет!H66,""),IF(Просчет!I67='Смета в налоговую'!C24,Просчет!H67,""),IF(Просчет!I68='Смета в налоговую'!C24,Просчет!H68,""),IF(Просчет!I69='Смета в налоговую'!C24,Просчет!H69,""),IF(Просчет!I70='Смета в налоговую'!C24,Просчет!H70,""),IF(Просчет!I71='Смета в налоговую'!C24,Просчет!H71,""),IF(Просчет!I72='Смета в налоговую'!C24,Просчет!H72,""),IF(Просчет!I73='Смета в налоговую'!C24,Просчет!H73,""),IF(Просчет!I74='Смета в налоговую'!C24,Просчет!H74,""),IF(Просчет!I75='Смета в налоговую'!C24,Просчет!H75,""),IF(Просчет!I76='Смета в налоговую'!C24,Просчет!H76,""),IF(Просчет!I77='Смета в налоговую'!C24,Просчет!H77,""),IF(Просчет!I78='Смета в налоговую'!C24,Просчет!H78,"")) | C24: Брус 25х50 мм | D24: =0.025*0.05*3*Просчет!B56 -> 0 | E24: м3 | F24: 11500 | G24: =F24/1.25*0.55 -> 5060 | H24: =(F24+G24)*D24 -> 0
B25: =_xlfn.TEXTJOIN(", ",,IF(Просчет!I57='Смета в налоговую'!C25,Просчет!H57,""),IF(Просчет!I58='Смета в налоговую'!C25,Просчет!H58,""),IF(Просчет!I59='Смета в налоговую'!C25,Просчет!H59,""),IF(Просчет!I60='Смета в налоговую'!C25,Просчет!H60,""),IF(Просчет!I61='Смета в налоговую'!C25,Просчет!H61,""),IF(Просчет!I62='Смета в налоговую'!C25,Просчет!H62,""),IF(Просчет!I63='Смета в налоговую'!C25,Просчет!H63,""),IF(Просчет!I64='Смета в налоговую'!C25,Просчет!H64,""),IF(Просчет!I65='Смета в налоговую'!C25,Просчет!H65,""),IF(Просчет!I66='Смета в налоговую'!C25,Просчет!H66,""),IF(Просчет!I67='Смета в налоговую'!C25,Просчет!H67,""),IF(Просчет!I68='Смета в налоговую'!C25,Просчет!H68,""),IF(Просчет!I69='Смета в налоговую'!C25,Просчет!H69,""),IF(Просчет!I70='Смета в налоговую'!C25,Просчет!H70,""),IF(Просчет!I71='Смета в налоговую'!C25,Просчет!H71,""),IF(Просчет!I72='Смета в налоговую'!C25,Просчет!H72,""),IF(Просчет!I73='Смета в налоговую'!C25,Просчет!H73,""),IF(Просчет!I74='Смета в налоговую'!C25,Просчет!H74,""),IF(Просчет!I75='Смета в налоговую'!C25,Просчет!H75,""),IF(Просчет!I76='Смета в налоговую'!C25,Просчет!H76,""),IF(Просчет!I77='Смета в налоговую'!C25,Просчет!H77,""),IF(Просчет!I78='Смета в налоговую'!C25,Просчет!H78,""),IF(Просчет!I56='Смета в налоговую'!C25,Просчет!H56,"")) | C25: Брус 25х100 мм | D25: =0.025*0.1*6*Просчет!B57 -> 0 | E25: м3 | F25: 11500 | G25: =F25/1.25*0.55 -> 5060 | H25: =(F25+G25)*D25 -> 0
B26: =_xlfn.TEXTJOIN(", ",,IF(Просчет!I58='Смета в налоговую'!C26,Просчет!H58,""),IF(Просчет!I59='Смета в налоговую'!C26,Просчет!H59,""),IF(Просчет!I60='Смета в налоговую'!C26,Просчет!H60,""),IF(Просчет!I61='Смета в налоговую'!C26,Просчет!H61,""),IF(Просчет!I62='Смета в налоговую'!C26,Просчет!H62,""),IF(Просчет!I63='Смета в налоговую'!C26,Просчет!H63,""),IF(Просчет!I64='Смета в налоговую'!C26,Просчет!H64,""),IF(Просчет!I65='Смета в налоговую'!C26,Просчет!H65,""),IF(Просчет!I66='Смета в налоговую'!C26,Просчет!H66,""),IF(Просчет!I67='Смета в налоговую'!C26,Просчет!H67,""),IF(Просчет!I68='Смета в налоговую'!C26,Просчет!H68,""),IF(Просчет!I69='Смета в налоговую'!C26,Просчет!H69,""),IF(Просчет!I70='Смета в налоговую'!C26,Просчет!H70,""),IF(Просчет!I71='Смета в налоговую'!C26,Просчет!H71,""),IF(Просчет!I72='Смета в налоговую'!C26,Просчет!H72,""),IF(Просчет!I73='Смета в налоговую'!C26,Просчет!H73,""),IF(Просчет!I74='Смета в налоговую'!C26,Просчет!H74,""),IF(Просчет!I75='Смета в налоговую'!C26,Просчет!H75,""),IF(Просчет!I76='Смета в налоговую'!C26,Просчет!H76,""),IF(Просчет!I77='Смета в налоговую'!C26,Просчет!H77,""),IF(Просчет!I78='Смета в налоговую'!C26,Просчет!H78,""),IF(Просчет!I56='Смета в налоговую'!C26,Просчет!H56,""),IF(Просчет!I57='Смета в налоговую'!C26,Просчет!H57,"")) | C26: Брус 2-го сорта 25х100 мм | D26: =0.025*0.1*6*Просчет!B58 -> 0 | E26: м3 | F26: 7125 | G26: =F26/1.25*0.55 -> 3135 | H26: =(F26+G26)*D26 -> 0
B27: =_xlfn.TEXTJOIN(", ",,IF(Просчет!I59='Смета в налоговую'!C27,Просчет!H59,""),IF(Просчет!I60='Смета в налоговую'!C27,Просчет!H60,""),IF(Просчет!I61='Смета в налоговую'!C27,Просчет!H61,""),IF(Просчет!I62='Смета в налоговую'!C27,Просчет!H62,""),IF(Просчет!I63='Смета в налоговую'!C27,Просчет!H63,""),IF(Просчет!I64='Смета в налоговую'!C27,Просчет!H64,""),IF(Просчет!I65='Смета в налоговую'!C27,Просчет!H65,""),IF(Просчет!I66='Смета в налоговую'!C27,Просчет!H66,""),IF(Просчет!I67='Смета в налоговую'!C27,Просчет!H67,""),IF(Просчет!I68='Смета в налоговую'!C27,Просчет!H68,""),IF(Просчет!I69='Смета в налоговую'!C27,Просчет!H69,""),IF(Просчет!I70='Смета в налоговую'!C27,Просчет!H70,""),IF(Просчет!I71='Смета в налоговую'!C27,Просчет!H71,""),IF(Просчет!I72='Смета в налоговую'!C27,Просчет!H72,""),IF(Просчет!I73='Смета в налоговую'!C27,Просчет!H73,""),IF(Просчет!I74='Смета в налоговую'!C27,Просчет!H74,""),IF(Просчет!I75='Смета в налоговую'!C27,Просчет!H75,""),IF(Просчет!I76='Смета в налоговую'!C27,Просчет!H76,""),IF(Просчет!I77='Смета в налоговую'!C27,Просчет!H77,""),IF(Просчет!I78='Смета в налоговую'!C27,Просчет!H78,""),IF(Просчет!I56='Смета в налоговую'!C27,Просчет!H56,""),IF(Просчет!I57='Смета в налоговую'!C27,Просчет!H57,""),IF(Просчет!I58='Смета в налоговую'!C27,Просчет!H58,"")) | C27: Брус 25х150 мм | D27: =0.025*0.15*6*Просчет!B59 -> 0 | E27: м3 | F27: 11500 | G27: =F27/1.25*0.55 -> 5060 | H27: =(F27+G27)*D27 -> 0
B28: =_xlfn.TEXTJOIN(", ",,IF(Просчет!I60='Смета в налоговую'!C28,Просчет!H60,""),IF(Просчет!I61='Смета в налоговую'!C28,Просчет!H61,""),IF(Просчет!I62='Смета в налоговую'!C28,Просчет!H62,""),IF(Просчет!I63='Смета в налоговую'!C28,Просчет!H63,""),IF(Просчет!I64='Смета в налоговую'!C28,Просчет!H64,""),IF(Просчет!I65='Смета в налоговую'!C28,Просчет!H65,""),IF(Просчет!I66='Смета в налоговую'!C28,Просчет!H66,""),IF(Просчет!I67='Смета в налоговую'!C28,Просчет!H67,""),IF(Просчет!I68='Смета в налоговую'!C28,Просчет!H68,""),IF(Просчет!I69='Смета в налоговую'!C28,Просчет!H69,""),IF(Просчет!I70='Смета в налоговую'!C28,Просчет!H70,""),IF(Просчет!I71='Смета в налоговую'!C28,Просчет!H71,""),IF(Просчет!I72='Смета в налоговую'!C28,Просчет!H72,""),IF(Просчет!I73='Смета в налоговую'!C28,Просчет!H73,""),IF(Просчет!I74='Смета в налоговую'!C28,Просчет!H74,""),IF(Просчет!I75='Смета в налоговую'!C28,Просчет!H75,""),IF(Просчет!I76='Смета в налоговую'!C28,Просчет!H76,""),IF(Просчет!I77='Смета в налоговую'!C28,Просчет!H77,""),IF(Просчет!I78='Смета в налоговую'!C28,Просчет!H78,""),IF(Просчет!I56='Смета в налоговую'!C28,Просчет!H56,""),IF(Просчет!I57='Смета в налоговую'!C28,Просчет!H57,""),IF(Просчет!I58='Смета в налоговую'!C28,Просчет!H58,""),IF(Просчет!I59='Смета в налоговую'!C28,Просчет!H59,"")) | C28: Брус 25х200 мм | D28: =0.025*0.2*6*Просчет!B60 -> 0 | E28: м3 | F28: 11500 | G28: =F28/1.25*0.55 -> 5060 | H28: =(F28+G28)*D28 -> 0
B29: =_xlfn.TEXTJOIN(", ",,IF(Просчет!I61='Смета в налоговую'!C29,Просчет!H61,""),IF(Просчет!I62='Смета в налоговую'!C29,Просчет!H62,""),IF(Просчет!I63='Смета в налоговую'!C29,Просчет!H63,""),IF(Просчет!I64='Смета в налоговую'!C29,Просчет!H64,""),IF(Просчет!I65='Смета в налоговую'!C29,Просчет!H65,""),IF(Просчет!I66='Смета в налоговую'!C29,Просчет!H66,""),IF(Просчет!I67='Смета в налоговую'!C29,Просчет!H67,""),IF(Просчет!I68='Смета в налоговую'!C29,Просчет!H68,""),IF(Просчет!I69='Смета в налоговую'!C29,Просчет!H69,""),IF(Просчет!I70='Смета в налоговую'!C29,Просчет!H70,""),IF(Просчет!I71='Смета в налоговую'!C29,Просчет!H71,""),IF(Просчет!I72='Смета в налоговую'!C29,Просчет!H72,""),IF(Просчет!I73='Смета в налоговую'!C29,Просчет!H73,""),IF(Просчет!I74='Смета в налоговую'!C29,Просчет!H74,""),IF(Просчет!I75='Смета в налоговую'!C29,Просчет!H75,""),IF(Просчет!I76='Смета в налоговую'!C29,Просчет!H76,""),IF(Просчет!I77='Смета в налоговую'!C29,Просчет!H77,""),IF(Просчет!I78='Смета в налоговую'!C29,Просчет!H78,""),IF(Просчет!I56='Смета в налоговую'!C29,Просчет!H56,""),IF(Просчет!I57='Смета в налоговую'!C29,Просчет!H57,""),IF(Просчет!I58='Смета в налоговую'!C29,Просчет!H58,""),IF(Просчет!I59='Смета в налоговую'!C29,Просчет!H59,""),IF(Просчет!I60='Смета в налоговую'!C29,Просчет!H60,"")) | C29: Брус 40х50 мм | D29: =0.04*0.05*3*Просчет!B61 -> 0 | E29: м3 | F29: 11500 | G29: =F29/1.25*0.55 -> 5060 | H29: =(F29+G29)*D29 -> 0
B30: =_xlfn.TEXTJOIN(", ",,IF(Просчет!I62='Смета в налоговую'!C30,Просчет!H62,""),IF(Просчет!I63='Смета в налоговую'!C30,Просчет!H63,""),IF(Просчет!I64='Смета в налоговую'!C30,Просчет!H64,""),IF(Просчет!I65='Смета в налоговую'!C30,Просчет!H65,""),IF(Просчет!I66='Смета в налоговую'!C30,Просчет!H66,""),IF(Просчет!I67='Смета в налоговую'!C30,Просчет!H67,""),IF(Просчет!I68='Смета в налоговую'!C30,Просчет!H68,""),IF(Просчет!I69='Смета в налоговую'!C30,Просчет!H69,""),IF(Просчет!I70='Смета в налоговую'!C30,Просчет!H70,""),IF(Просчет!I71='Смета в налоговую'!C30,Просчет!H71,""),IF(Просчет!I72='Смета в налоговую'!C30,Просчет!H72,""),IF(Просчет!I73='Смета в налоговую'!C30,Просчет!H73,""),IF(Просчет!I74='Смета в налоговую'!C30,Просчет!H74,""),IF(Просчет!I75='Смета в налоговую'!C30,Просчет!H75,""),IF(Просчет!I76='Смета в налоговую'!C30,Просчет!H76,""),IF(Просчет!I77='Смета в налоговую'!C30,Просчет!H77,""),IF(Просчет!I78='Смета в налоговую'!C30,Просчет!H78,""),IF(Просчет!I56='Смета в налоговую'!C30,Просчет!H56,""),IF(Просчет!I57='Смета в налоговую'!C30,Просчет!H57,""),IF(Просчет!I58='Смета в налоговую'!C30,Просчет!H58,""),IF(Просчет!I59='Смета в налоговую'!C30,Просчет!H59,""),IF(Просчет!I60='Смета в налоговую'!C30,Просчет!H60,""),IF(Просчет!I61='Смета в налоговую'!C30,Просчет!H61,"")) | C30: Брус 50х50 мм | D30: =0.05*0.05*3*Просчет!B62 -> 0 | E30: м3 | F30: 11500 | G30: =F30/1.25*0.55 -> 5060 | H30: =(F30+G30)*D30 -> 0
B31: =_xlfn.TEXTJOIN(", ",,IF(Просчет!I63='Смета в налоговую'!C31,Просчет!H63,""),IF(Просчет!I64='Смета в налоговую'!C31,Просчет!H64,""),IF(Просчет!I65='Смета в налоговую'!C31,Просчет!H65,""),IF(Просчет!I66='Смета в налоговую'!C31,Просчет!H66,""),IF(Просчет!I67='Смета в налоговую'!C31,Просчет!H67,""),IF(Просчет!I68='Смета в налоговую'!C31,Просчет!H68,""),IF(Просчет!I69='Смета в налоговую'!C31,Просчет!H69,""),IF(Просчет!I70='Смета в налоговую'!C31,Просчет!H70,""),IF(Просчет!I71='Смета в налоговую'!C31,Просчет!H71,""),IF(Просчет!I72='Смета в налоговую'!C31,Просчет!H72,""),IF(Просчет!I73='Смета в налоговую'!C31,Просчет!H73,""),IF(Просчет!I74='Смета в налоговую'!C31,Просчет!H74,""),IF(Просчет!I75='Смета в налоговую'!C31,Просчет!H75,""),IF(Просчет!I76='Смета в налоговую'!C31,Просчет!H76,""),IF(Просчет!I77='Смета в налоговую'!C31,Просчет!H77,""),IF(Просчет!I78='Смета в налоговую'!C31,Просчет!H78,""),IF(Просчет!I56='Смета в налоговую'!C31,Просчет!H56,""),IF(Просчет!I57='Смета в налоговую'!C31,Просчет!H57,""),IF(Просчет!I58='Смета в налоговую'!C31,Просчет!H58,""),IF(Просчет!I59='Смета в налоговую'!C31,Просчет!H59,""),IF(Просчет!I60='Смета в налоговую'!C31,Просчет!H60,""),IF(Просчет!I61='Смета в налоговую'!C31,Просчет!H61,""),IF(Просчет!I62='Смета в налоговую'!C31,Просчет!H62,"")) | C31: Брус 50х100 мм | D31: =0.05*0.1*6*(Просчет!B63+Просчет!B32) -> 0 | E31: м3 | F31: 11500 | G31: =F31/1.25*0.55 -> 5060 | H31: =(F31+G31)*D31 -> 0
B32: =_xlfn.TEXTJOIN(", ",,IF(Просчет!I64='Смета в налоговую'!C32,Просчет!H64,""),IF(Просчет!I65='Смета в налоговую'!C32,Просчет!H65,""),IF(Просчет!I66='Смета в налоговую'!C32,Просчет!H66,""),IF(Просчет!I67='Смета в налоговую'!C32,Просчет!H67,""),IF(Просчет!I68='Смета в налоговую'!C32,Просчет!H68,""),IF(Просчет!I69='Смета в налоговую'!C32,Просчет!H69,""),IF(Просчет!I70='Смета в налоговую'!C32,Просчет!H70,""),IF(Просчет!I71='Смета в налоговую'!C32,Просчет!H71,""),IF(Просчет!I72='Смета в налоговую'!C32,Просчет!H72,""),IF(Просчет!I73='Смета в налоговую'!C32,Просчет!H73,""),IF(Просчет!I74='Смета в налоговую'!C32,Просчет!H74,""),IF(Просчет!I75='Смета в налоговую'!C32,Просчет!H75,""),IF(Просчет!I76='Смета в налоговую'!C32,Просчет!H76,""),IF(Просчет!I77='Смета в налоговую'!C32,Просчет!H77,""),IF(Просчет!I78='Смета в налоговую'!C32,Просчет!H78,""),IF(Просчет!I56='Смета в налоговую'!C32,Просчет!H56,""),IF(Просчет!I57='Смета в налоговую'!C32,Просчет!H57,""),IF(Просчет!I58='Смета в налоговую'!C32,Просчет!H58,""),IF(Просчет!I59='Смета в налоговую'!C32,Просчет!H59,""),IF(Просчет!I60='Смета в налоговую'!C32,Просчет!H60,""),IF(Просчет!I61='Смета в налоговую'!C32,Просчет!H61,""),IF(Просчет!I62='Смета в налоговую'!C32,Просчет!H62,""),IF(Просчет!I63='Смета в налоговую'!C32,Просчет!H63,"")) | C32: Брус 50х150 мм | D32: =0.05*0.15*6*(Просчет!B64+Просчет!B33) -> 0 | E32: м3 | F32: 11500 | G32: =F32/1.25*0.55 -> 5060 | H32: =(F32+G32)*D32 -> 0
B33: =_xlfn.TEXTJOIN(", ",,IF(Просчет!I65='Смета в налоговую'!C33,Просчет!H65,""),IF(Просчет!I66='Смета в налоговую'!C33,Просчет!H66,""),IF(Просчет!I67='Смета в налоговую'!C33,Просчет!H67,""),IF(Просчет!I68='Смета в налоговую'!C33,Просчет!H68,""),IF(Просчет!I69='Смета в налоговую'!C33,Просчет!H69,""),IF(Просчет!I70='Смета в налоговую'!C33,Просчет!H70,""),IF(Просчет!I71='Смета в налоговую'!C33,Просчет!H71,""),IF(Просчет!I72='Смета в налоговую'!C33,Просчет!H72,""),IF(Просчет!I73='Смета в налоговую'!C33,Просчет!H73,""),IF(Просчет!I74='Смета в налоговую'!C33,Просчет!H74,""),IF(Просчет!I75='Смета в налоговую'!C33,Просчет!H75,""),IF(Просчет!I76='Смета в налоговую'!C33,Просчет!H76,""),IF(Просчет!I77='Смета в налоговую'!C33,Просчет!H77,""),IF(Просчет!I78='Смета в налоговую'!C33,Просчет!H78,""),IF(Просчет!I56='Смета в налоговую'!C33,Просчет!H56,""),IF(Просчет!I57='Смета в налоговую'!C33,Просчет!H57,""),IF(Просчет!I58='Смета в налоговую'!C33,Просчет!H58,""),IF(Просчет!I59='Смета в налоговую'!C33,Просчет!H59,""),IF(Просчет!I60='Смета в налоговую'!C33,Просчет!H60,""),IF(Просчет!I61='Смета в налоговую'!C33,Просчет!H61,""),IF(Просчет!I62='Смета в налоговую'!C33,Просчет!H62,""),IF(Просчет!I63='Смета в налоговую'!C33,Просчет!H63,""),IF(Просчет!I64='Смета в налоговую'!C33,Просчет!H64,"")) | C33: Брус 50х200 мм | D33: =0.05*0.2*6*(Просчет!B65+Просчет!B34) -> 0 | E33: м3 | F33: 11500 | G33: =F33/1.25*0.55 -> 5060 | H33: =(F33+G33)*D33 -> 0
B34: =_xlfn.TEXTJOIN(", ",,IF(Просчет!I66='Смета в налоговую'!C34,Просчет!H66,""),IF(Просчет!I67='Смета в налоговую'!C34,Просчет!H67,""),IF(Просчет!I68='Смета в налоговую'!C34,Просчет!H68,""),IF(Просчет!I69='Смета в налоговую'!C34,Просчет!H69,""),IF(Просчет!I70='Смета в налоговую'!C34,Просчет!H70,""),IF(Просчет!I71='Смета в налоговую'!C34,Просчет!H71,""),IF(Просчет!I72='Смета в налоговую'!C34,Просчет!H72,""),IF(Просчет!I73='Смета в налоговую'!C34,Просчет!H73,""),IF(Просчет!I74='Смета в налоговую'!C34,Просчет!H74,""),IF(Просчет!I75='Смета в налоговую'!C34,Просчет!H75,""),IF(Просчет!I76='Смета в налоговую'!C34,Просчет!H76,""),IF(Просчет!I77='Смета в налоговую'!C34,Просчет!H77,""),IF(Просчет!I78='Смета в налоговую'!C34,Просчет!H78,""),IF(Просчет!I56='Смета в налоговую'!C34,Просчет!H56,""),IF(Просчет!I57='Смета в налоговую'!C34,Просчет!H57,""),IF(Просчет!I58='Смета в налоговую'!C34,Просчет!H58,""),IF(Просчет!I59='Смета в налоговую'!C34,Просчет!H59,""),IF(Просчет!I60='Смета в налоговую'!C34,Просчет!H60,""),IF(Просчет!I61='Смета в налоговую'!C34,Просчет!H61,""),IF(Просчет!I62='Смета в налоговую'!C34,Просчет!H62,""),IF(Просчет!I63='Смета в налоговую'!C34,Просчет!H63,""),IF(Просчет!I64='Смета в налоговую'!C34,Просчет!H64,""),IF(Просчет!I65='Смета в налоговую'!C34,Просчет!H65,"")) | C34: Брус 100х100 мм | D34: =0.1*0.1*6*(Просчет!B66+Просчет!B35) -> 0 | E34: м3 | F34: 11500 | G34: =F34/1.25*0.55 -> 5060 | H34: =(F34+G34)*D34 -> 0
B35: =_xlfn.TEXTJOIN(", ",,IF(Просчет!I67='Смета в налоговую'!C35,Просчет!H67,""),IF(Просчет!I68='Смета в налоговую'!C35,Просчет!H68,""),IF(Просчет!I69='Смета в налоговую'!C35,Просчет!H69,""),IF(Просчет!I70='Смета в налоговую'!C35,Просчет!H70,""),IF(Просчет!I71='Смета в налоговую'!C35,Просчет!H71,""),IF(Просчет!I72='Смета в налоговую'!C35,Просчет!H72,""),IF(Просчет!I73='Смета в налоговую'!C35,Просчет!H73,""),IF(Просчет!I74='Смета в налоговую'!C35,Просчет!H74,""),IF(Просчет!I75='Смета в налоговую'!C35,Просчет!H75,""),IF(Просчет!I76='Смета в налоговую'!C35,Просчет!H76,""),IF(Просчет!I77='Смета в налоговую'!C35,Просчет!H77,""),IF(Просчет!I78='Смета в налоговую'!C35,Просчет!H78,""),IF(Просчет!I56='Смета в налоговую'!C35,Просчет!H56,""),IF(Просчет!I57='Смета в налоговую'!C35,Просчет!H57,""),IF(Просчет!I58='Смета в налоговую'!C35,Просчет!H58,""),IF(Просчет!I59='Смета в налоговую'!C35,Просчет!H59,""),IF(Просчет!I60='Смета в налоговую'!C35,Просчет!H60,""),IF(Просчет!I61='Смета в налоговую'!C35,Просчет!H61,""),IF(Просчет!I62='Смета в налоговую'!C35,Просчет!H62,""),IF(Просчет!I63='Смета в налоговую'!C35,Просчет!H63,""),IF(Просчет!I64='Смета в налоговую'!C35,Просчет!H64,""),IF(Просчет!I65='Смета в налоговую'!C35,Просчет!H65,""),IF(Просчет!I66='Смета в налоговую'!C35,Просчет!H66,"")) | C35: Брус 100х150 мм | D35: =0.1*0.15*6*(Просчет!B67+Просчет!B36) -> 0 | E35: м3 | F35: 11500 | G35: =F35/1.25*0.55 -> 5060 | H35: =(F35+G35)*D35 -> 0
B36: =_xlfn.TEXTJOIN(", ",,IF(Просчет!I68='Смета в налоговую'!C36,Просчет!H68,""),IF(Просчет!I69='Смета в налоговую'!C36,Просчет!H69,""),IF(Просчет!I70='Смета в налоговую'!C36,Просчет!H70,""),IF(Просчет!I71='Смета в налоговую'!C36,Просчет!H71,""),IF(Просчет!I72='Смета в налоговую'!C36,Просчет!H72,""),IF(Просчет!I73='Смета в налоговую'!C36,Просчет!H73,""),IF(Просчет!I74='Смета в налоговую'!C36,Просчет!H74,""),IF(Просчет!I75='Смета в налоговую'!C36,Просчет!H75,""),IF(Просчет!I76='Смета в налоговую'!C36,Просчет!H76,""),IF(Просчет!I77='Смета в налоговую'!C36,Просчет!H77,""),IF(Просчет!I78='Смета в налоговую'!C36,Просчет!H78,""),IF(Просчет!I56='Смета в налоговую'!C36,Просчет!H56,""),IF(Просчет!I57='Смета в налоговую'!C36,Просчет!H57,""),IF(Просчет!I58='Смета в налоговую'!C36,Просчет!H58,""),IF(Просчет!I59='Смета в налоговую'!C36,Просчет!H59,""),IF(Просчет!I60='Смета в налоговую'!C36,Просчет!H60,""),IF(Просчет!I61='Смета в налоговую'!C36,Просчет!H61,""),IF(Просчет!I62='Смета в налоговую'!C36,Просчет!H62,""),IF(Просчет!I63='Смета в налоговую'!C36,Просчет!H63,""),IF(Просчет!I64='Смета в налоговую'!C36,Просчет!H64,""),IF(Просчет!I65='Смета в налоговую'!C36,Просчет!H65,""),IF(Просчет!I66='Смета в налоговую'!C36,Просчет!H66,""),IF(Просчет!I67='Смета в налоговую'!C36,Просчет!H67,"")) | C36: Брус 100х200 мм | D36: =0.1*0.2*6*(Просчет!B68+Просчет!B37) -> 0 | E36: м3 | F36: 11500 | G36: =F36/1.25*0.55 -> 5060 | H36: =(F36+G36)*D36 -> 0
B37: =_xlfn.TEXTJOIN(", ",,IF(Просчет!I69='Смета в налоговую'!C37,Просчет!H69,""),IF(Просчет!I70='Смета в налоговую'!C37,Просчет!H70,""),IF(Просчет!I71='Смета в налоговую'!C37,Просчет!H71,""),IF(Просчет!I72='Смета в налоговую'!C37,Просчет!H72,""),IF(Просчет!I73='Смета в налоговую'!C37,Просчет!H73,""),IF(Просчет!I74='Смета в налоговую'!C37,Просчет!H74,""),IF(Просчет!I75='Смета в налоговую'!C37,Просчет!H75,""),IF(Просчет!I76='Смета в налоговую'!C37,Просчет!H76,""),IF(Просчет!I77='Смета в налоговую'!C37,Просчет!H77,""),IF(Просчет!I78='Смета в налоговую'!C37,Просчет!H78,""),IF(Просчет!I56='Смета в налоговую'!C37,Просчет!H56,""),IF(Просчет!I57='Смета в налоговую'!C37,Просчет!H57,""),IF(Просчет!I58='Смета в налоговую'!C37,Просчет!H58,""),IF(Просчет!I59='Смета в налоговую'!C37,Просчет!H59,""),IF(Просчет!I60='Смета в налоговую'!C37,Просчет!H60,""),IF(Просчет!I61='Смета в налоговую'!C37,Просчет!H61,""),IF(Просчет!I62='Смета в налоговую'!C37,Просчет!H62,""),IF(Просчет!I63='Смета в налоговую'!C37,Просчет!H63,""),IF(Просчет!I64='Смета в налоговую'!C37,Просчет!H64,""),IF(Просчет!I65='Смета в налоговую'!C37,Просчет!H65,""),IF(Просчет!I66='Смета в налоговую'!C37,Просчет!H66,""),IF(Просчет!I67='Смета в налоговую'!C37,Просчет!H67,""),IF(Просчет!I68='Смета в налоговую'!C37,Просчет!H68,"")) | C37: Брус 150х150 мм | D37: =0.15*0.15*6*(Просчет!B69+Просчет!B38) -> 0 | E37: м3 | F37: 11500 | G37: =F37/1.25*0.55 -> 5060 | H37: =(F37+G37)*D37 -> 0
B38: =_xlfn.TEXTJOIN(", ",,IF(Просчет!I70='Смета в налоговую'!C38,Просчет!H70,""),IF(Просчет!I71='Смета в налоговую'!C38,Просчет!H71,""),IF(Просчет!I72='Смета в налоговую'!C38,Просчет!H72,""),IF(Просчет!I73='Смета в налоговую'!C38,Просчет!H73,""),IF(Просчет!I74='Смета в налоговую'!C38,Просчет!H74,""),IF(Просчет!I75='Смета в налоговую'!C38,Просчет!H75,""),IF(Просчет!I76='Смета в налоговую'!C38,Просчет!H76,""),IF(Просчет!I77='Смета в налоговую'!C38,Просчет!H77,""),IF(Просчет!I78='Смета в налоговую'!C38,Просчет!H78,""),IF(Просчет!I56='Смета в налоговую'!C38,Просчет!H56,""),IF(Просчет!I57='Смета в налоговую'!C38,Просчет!H57,""),IF(Просчет!I58='Смета в налоговую'!C38,Просчет!H58,""),IF(Просчет!I59='Смета в налоговую'!C38,Просчет!H59,""),IF(Просчет!I60='Смета в налоговую'!C38,Просчет!H60,""),IF(Просчет!I61='Смета в налоговую'!C38,Просчет!H61,""),IF(Просчет!I62='Смета в налоговую'!C38,Просчет!H62,""),IF(Просчет!I63='Смета в налоговую'!C38,Просчет!H63,""),IF(Просчет!I64='Смета в налоговую'!C38,Просчет!H64,""),IF(Просчет!I65='Смета в налоговую'!C38,Просчет!H65,""),IF(Просчет!I66='Смета в налоговую'!C38,Просчет!H66,""),IF(Просчет!I67='Смета в налоговую'!C38,Просчет!H67,""),IF(Просчет!I68='Смета в налоговую'!C38,Просчет!H68,""),IF(Просчет!I69='Смета в налоговую'!C38,Просчет!H69,"")) | C38: Брус 150х200 мм | D38: =0.15*0.2*6*(Просчет!B70+Просчет!B39) -> 0 | E38: м3 | F38: 11500 | G38: =F38/1.25*0.55 -> 5060 | H38: =(F38+G38)*D38 -> 0
B39: =_xlfn.TEXTJOIN(", ",,IF(Просчет!I71='Смета в налоговую'!C39,Просчет!H71,""),IF(Просчет!I72='Смета в налоговую'!C39,Просчет!H72,""),IF(Просчет!I73='Смета в налоговую'!C39,Просчет!H73,""),IF(Просчет!I74='Смета в налоговую'!C39,Просчет!H74,""),IF(Просчет!I75='Смета в налоговую'!C39,Просчет!H75,""),IF(Просчет!I76='Смета в налоговую'!C39,Просчет!H76,""),IF(Просчет!I77='Смета в налоговую'!C39,Просчет!H77,""),IF(Просчет!I78='Смета в налоговую'!C39,Просчет!H78,""),IF(Просчет!I56='Смета в налоговую'!C39,Просчет!H56,""),IF(Просчет!I57='Смета в налоговую'!C39,Просчет!H57,""),IF(Просчет!I58='Смета в налоговую'!C39,Просчет!H58,""),IF(Просчет!I59='Смета в налоговую'!C39,Просчет!H59,""),IF(Просчет!I60='Смета в налоговую'!C39,Просчет!H60,""),IF(Просчет!I61='Смета в налоговую'!C39,Просчет!H61,""),IF(Просчет!I62='Смета в налоговую'!C39,Просчет!H62,""),IF(Просчет!I63='Смета в налоговую'!C39,Просчет!H63,""),IF(Просчет!I64='Смета в налоговую'!C39,Просчет!H64,""),IF(Просчет!I65='Смета в налоговую'!C39,Просчет!H65,""),IF(Просчет!I66='Смета в налоговую'!C39,Просчет!H66,""),IF(Просчет!I67='Смета в налоговую'!C39,Просчет!H67,""),IF(Просчет!I68='Смета в налоговую'!C39,Просчет!H68,""),IF(Просчет!I69='Смета в налоговую'!C39,Просчет!H69,""),IF(Просчет!I70='Смета в налоговую'!C39,Просчет!H70,"")) | C39: Брус 200х200 мм | D39: =0.2*0.2*6*(Просчет!B71+Просчет!B40) -> 0 | E39: м3 | F39: 11500 | G39: =F39/1.25*0.55 -> 5060 | H39: =(F39+G39)*D39 -> 0
B40: =_xlfn.TEXTJOIN(", ",,IF(Просчет!I72='Смета в налоговую'!C40,Просчет!H72,""),IF(Просчет!I73='Смета в налоговую'!C40,Просчет!H73,""),IF(Просчет!I74='Смета в налоговую'!C40,Просчет!H74,""),IF(Просчет!I75='Смета в налоговую'!C40,Просчет!H75,""),IF(Просчет!I76='Смета в налоговую'!C40,Просчет!H76,""),IF(Просчет!I77='Смета в налоговую'!C40,Просчет!H77,""),IF(Просчет!I78='Смета в налоговую'!C40,Просчет!H78,""),IF(Просчет!I56='Смета в налоговую'!C40,Просчет!H56,""),IF(Просчет!I57='Смета в налоговую'!C40,Просчет!H57,""),IF(Просчет!I58='Смета в налоговую'!C40,Просчет!H58,""),IF(Просчет!I59='Смета в налоговую'!C40,Просчет!H59,""),IF(Просчет!I60='Смета в налоговую'!C40,Просчет!H60,""),IF(Просчет!I61='Смета в налоговую'!C40,Просчет!H61,""),IF(Просчет!I62='Смета в налоговую'!C40,Просчет!H62,""),IF(Просчет!I63='Смета в налоговую'!C40,Просчет!H63,""),IF(Просчет!I64='Смета в налоговую'!C40,Просчет!H64,""),IF(Просчет!I65='Смета в налоговую'!C40,Просчет!H65,""),IF(Просчет!I66='Смета в налоговую'!C40,Просчет!H66,""),IF(Просчет!I67='Смета в налоговую'!C40,Просчет!H67,""),IF(Просчет!I68='Смета в налоговую'!C40,Просчет!H68,""),IF(Просчет!I69='Смета в налоговую'!C40,Просчет!H69,""),IF(Просчет!I70='Смета в налоговую'!C40,Просчет!H70,""),IF(Просчет!I71='Смета в налоговую'!C40,Просчет!H71,"")) | C40: Брус сухой, нестроганый 25х50 мм | D40: =0.025*0.05*3*Просчет!B73 -> 0 | E40: м3 | F40: 13500 | G40: =F40/1.25*0.55 -> 5940 | H40: =(F40+G40)*D40 -> 0
B41: =_xlfn.TEXTJOIN(", ",,IF(Просчет!I73='Смета в налоговую'!C41,Просчет!H73,""),IF(Просчет!I74='Смета в налоговую'!C41,Просчет!H74,""),IF(Просчет!I75='Смета в налоговую'!C41,Просчет!H75,""),IF(Просчет!I76='Смета в налоговую'!C41,Просчет!H76,""),IF(Просчет!I77='Смета в налоговую'!C41,Просчет!H77,""),IF(Просчет!I78='Смета в налоговую'!C41,Просчет!H78,""),IF(Просчет!I56='Смета в налоговую'!C41,Просчет!H56,""),IF(Просчет!I57='Смета в налоговую'!C41,Просчет!H57,""),IF(Просчет!I58='Смета в налоговую'!C41,Просчет!H58,""),IF(Просчет!I59='Смета в налоговую'!C41,Просчет!H59,""),IF(Просчет!I60='Смета в налоговую'!C41,Просчет!H60,""),IF(Просчет!I61='Смета в налоговую'!C41,Просчет!H61,""),IF(Просчет!I62='Смета в налоговую'!C41,Просчет!H62,""),IF(Просчет!I63='Смета в налоговую'!C41,Просчет!H63,""),IF(Просчет!I64='Смета в налоговую'!C41,Просчет!H64,""),IF(Просчет!I65='Смета в налоговую'!C41,Просчет!H65,""),IF(Просчет!I66='Смета в налоговую'!C41,Просчет!H66,""),IF(Просчет!I67='Смета в налоговую'!C41,Просчет!H67,""),IF(Просчет!I68='Смета в налоговую'!C41,Просчет!H68,""),IF(Просчет!I69='Смета в налоговую'!C41,Просчет!H69,""),IF(Просчет!I70='Смета в налоговую'!C41,Просчет!H70,""),IF(Просчет!I71='Смета в налоговую'!C41,Просчет!H71,""),IF(Просчет!I72='Смета в налоговую'!C41,Просчет!H72,"")) | C41: Брус сухой, нестроганый 25х100 мм | D41: =0.025*0.1*6*Просчет!B74 -> 0 | E41: м3 | F41: 13500 | G41: =F41/1.25*0.55 -> 5940 | H41: =(F41+G41)*D41 -> 0
B42: =_xlfn.TEXTJOIN(", ",,IF(Просчет!I74='Смета в налоговую'!C42,Просчет!H74,""),IF(Просчет!I75='Смета в налоговую'!C42,Просчет!H75,""),IF(Просчет!I76='Смета в налоговую'!C42,Просчет!H76,""),IF(Просчет!I77='Смета в налоговую'!C42,Просчет!H77,""),IF(Просчет!I78='Смета в налоговую'!C42,Просчет!H78,""),IF(Просчет!I56='Смета в налоговую'!C42,Просчет!H56,""),IF(Просчет!I57='Смета в налоговую'!C42,Просчет!H57,""),IF(Просчет!I58='Смета в налоговую'!C42,Просчет!H58,""),IF(Просчет!I59='Смета в налоговую'!C42,Просчет!H59,""),IF(Просчет!I60='Смета в налоговую'!C42,Просчет!H60,""),IF(Просчет!I61='Смета в налоговую'!C42,Просчет!H61,""),IF(Просчет!I62='Смета в налоговую'!C42,Просчет!H62,""),IF(Просчет!I63='Смета в налоговую'!C42,Просчет!H63,""),IF(Просчет!I64='Смета в налоговую'!C42,Просчет!H64,""),IF(Просчет!I65='Смета в налоговую'!C42,Просчет!H65,""),IF(Просчет!I66='Смета в налоговую'!C42,Просчет!H66,""),IF(Просчет!I67='Смета в налоговую'!C42,Просчет!H67,""),IF(Просчет!I68='Смета в налоговую'!C42,Просчет!H68,""),IF(Просчет!I69='Смета в налоговую'!C42,Просчет!H69,""),IF(Просчет!I70='Смета в налоговую'!C42,Просчет!H70,""),IF(Просчет!I71='Смета в налоговую'!C42,Просчет!H71,""),IF(Просчет!I72='Смета в налоговую'!C42,Просчет!H72,""),IF(Просчет!I73='Смета в налоговую'!C42,Просчет!H73,"")) | C42: Брус 2-го сорта, сухой, нестроганый 25х100 мм | D42: =0.025*0.1*6*Просчет!B75 -> 0 | E42: м3 | F42: 9125 | G42: =F42/1.25*0.55 -> 4015 | H42: =(F42+G42)*D42 -> 0
B43: =_xlfn.TEXTJOIN(", ",,IF(Просчет!I75='Смета в налоговую'!C43,Просчет!H75,""),IF(Просчет!I76='Смета в налоговую'!C43,Просчет!H76,""),IF(Просчет!I77='Смета в налоговую'!C43,Просчет!H77,""),IF(Просчет!I78='Смета в налоговую'!C43,Просчет!H78,""),IF(Просчет!I56='Смета в налоговую'!C43,Просчет!H56,""),IF(Просчет!I57='Смета в налоговую'!C43,Просчет!H57,""),IF(Просчет!I58='Смета в налоговую'!C43,Просчет!H58,""),IF(Просчет!I59='Смета в налоговую'!C43,Просчет!H59,""),IF(Просчет!I60='Смета в налоговую'!C43,Просчет!H60,""),IF(Просчет!I61='Смета в налоговую'!C43,Просчет!H61,""),IF(Просчет!I62='Смета в налоговую'!C43,Просчет!H62,""),IF(Просчет!I63='Смета в налоговую'!C43,Просчет!H63,""),IF(Просчет!I64='Смета в налоговую'!C43,Просчет!H64,""),IF(Просчет!I65='Смета в налоговую'!C43,Просчет!H65,""),IF(Просчет!I66='Смета в налоговую'!C43,Просчет!H66,""),IF(Просчет!I67='Смета в налоговую'!C43,Просчет!H67,""),IF(Просчет!I68='Смета в налоговую'!C43,Просчет!H68,""),IF(Просчет!I69='Смета в налоговую'!C43,Просчет!H69,""),IF(Просчет!I70='Смета в налоговую'!C43,Просчет!H70,""),IF(Просчет!I71='Смета в налоговую'!C43,Просчет!H71,""),IF(Просчет!I72='Смета в налоговую'!C43,Просчет!H72,""),IF(Просчет!I73='Смета в налоговую'!C43,Просчет!H73,""),IF(Просчет!I74='Смета в налоговую'!C43,Просчет!H74,"")) | C43: Брус сухой, нестроганый 25х150 мм | D43: =0.025*0.15*6*Просчет!B76 -> 0 | E43: м3 | F43: 13500 | G43: =F43/1.25*0.55 -> 5940 | H43: =(F43+G43)*D43 -> 0
B44: =_xlfn.TEXTJOIN(", ",,IF(Просчет!I76='Смета в налоговую'!C44,Просчет!H76,""),IF(Просчет!I77='Смета в налоговую'!C44,Просчет!H77,""),IF(Просчет!I78='Смета в налоговую'!C44,Просчет!H78,""),IF(Просчет!I56='Смета в налоговую'!C44,Просчет!H56,""),IF(Просчет!I57='Смета в налоговую'!C44,Просчет!H57,""),IF(Просчет!I58='Смета в налоговую'!C44,Просчет!H58,""),IF(Просчет!I59='Смета в налоговую'!C44,Просчет!H59,""),IF(Просчет!I60='Смета в налоговую'!C44,Просчет!H60,""),IF(Просчет!I61='Смета в налоговую'!C44,Просчет!H61,""),IF(Просчет!I62='Смета в налоговую'!C44,Просчет!H62,""),IF(Просчет!I63='Смета в налоговую'!C44,Просчет!H63,""),IF(Просчет!I64='Смета в налоговую'!C44,Просчет!H64,""),IF(Просчет!I65='Смета в налоговую'!C44,Просчет!H65,""),IF(Просчет!I66='Смета в налоговую'!C44,Просчет!H66,""),IF(Просчет!I67='Смета в налоговую'!C44,Просчет!H67,""),IF(Просчет!I68='Смета в налоговую'!C44,Просчет!H68,""),IF(Просчет!I69='Смета в налоговую'!C44,Просчет!H69,""),IF(Просчет!I70='Смета в налоговую'!C44,Просчет!H70,""),IF(Просчет!I71='Смета в налоговую'!C44,Просчет!H71,""),IF(Просчет!I72='Смета в налоговую'!C44,Просчет!H72,""),IF(Просчет!I73='Смета в налоговую'!C44,Просчет!H73,""),IF(Просчет!I74='Смета в налоговую'!C44,Просчет!H74,""),IF(Просчет!I75='Смета в налоговую'!C44,Просчет!H75,"")) | C44: Брус сухой, нестроганый 25х200 мм | D44: =0.025*0.2*6*Просчет!B77 -> 0 | E44: м3 | F44: 13500 | G44: =F44/1.25*0.55 -> 5940 | H44: =(F44+G44)*D44 -> 0
B45: =_xlfn.TEXTJOIN(", ",,IF(Просчет!I77='Смета в налоговую'!C45,Просчет!H77,""),IF(Просчет!I78='Смета в налоговую'!C45,Просчет!H78,""),IF(Просчет!I56='Смета в налоговую'!C45,Просчет!H56,""),IF(Просчет!I57='Смета в налоговую'!C45,Просчет!H57,""),IF(Просчет!I58='Смета в налоговую'!C45,Просчет!H58,""),IF(Просчет!I59='Смета в налоговую'!C45,Просчет!H59,""),IF(Просчет!I60='Смета в налоговую'!C45,Просчет!H60,""),IF(Просчет!I61='Смета в налоговую'!C45,Просчет!H61,""),IF(Просчет!I62='Смета в налоговую'!C45,Просчет!H62,""),IF(Просчет!I63='Смета в налоговую'!C45,Просчет!H63,""),IF(Просчет!I64='Смета в налоговую'!C45,Просчет!H64,""),IF(Просчет!I65='Смета в налоговую'!C45,Просчет!H65,""),IF(Просчет!I66='Смета в налоговую'!C45,Просчет!H66,""),IF(Просчет!I67='Смета в налоговую'!C45,Просчет!H67,""),IF(Просчет!I68='Смета в налоговую'!C45,Просчет!H68,""),IF(Просчет!I69='Смета в налоговую'!C45,Просчет!H69,""),IF(Просчет!I70='Смета в налоговую'!C45,Просчет!H70,""),IF(Просчет!I71='Смета в налоговую'!C45,Просчет!H71,""),IF(Просчет!I72='Смета в налоговую'!C45,Просчет!H72,""),IF(Просчет!I73='Смета в налоговую'!C45,Просчет!H73,""),IF(Просчет!I74='Смета в налоговую'!C45,Просчет!H74,""),IF(Просчет!I75='Смета в налоговую'!C45,Просчет!H75,""),IF(Просчет!I76='Смета в налоговую'!C45,Просчет!H76,"")) | C45: Брус сухой, нестроганый 40х50 мм | D45: =0.04*0.05*3*Просчет!B78 -> 0 | E45: м3 | F45: 13500 | G45: =F45/1.25*0.55 -> 5940 | H45: =(F45+G45)*D45 -> 0
B46: =_xlfn.TEXTJOIN(", ",,IF(Просчет!I78='Смета в налоговую'!C46,Просчет!H78,""),IF(Просчет!I56='Смета в налоговую'!C46,Просчет!H56,""),IF(Просчет!I57='Смета в налоговую'!C46,Просчет!H57,""),IF(Просчет!I58='Смета в налоговую'!C46,Просчет!H58,""),IF(Просчет!I59='Смета в налоговую'!C46,Просчет!H59,""),IF(Просчет!I60='Смета в налоговую'!C46,Просчет!H60,""),IF(Просчет!I61='Смета в налоговую'!C46,Просчет!H61,""),IF(Просчет!I62='Смета в налоговую'!C46,Просчет!H62,""),IF(Просчет!I63='Смета в налоговую'!C46,Просчет!H63,""),IF(Просчет!I64='Смета в налоговую'!C46,Просчет!H64,""),IF(Просчет!I65='Смета в налоговую'!C46,Просчет!H65,""),IF(Просчет!I66='Смета в налоговую'!C46,Просчет!H66,""),IF(Просчет!I67='Смета в налоговую'!C46,Просчет!H67,""),IF(Просчет!I68='Смета в налоговую'!C46,Просчет!H68,""),IF(Просчет!I69='Смета в налоговую'!C46,Просчет!H69,""),IF(Просчет!I70='Смета в налоговую'!C46,Просчет!H70,""),IF(Просчет!I71='Смета в налоговую'!C46,Просчет!H71,""),IF(Просчет!I72='Смета в налоговую'!C46,Просчет!H72,""),IF(Просчет!I73='Смета в налоговую'!C46,Просчет!H73,""),IF(Просчет!I74='Смета в налоговую'!C46,Просчет!H74,""),IF(Просчет!I75='Смета в налоговую'!C46,Просчет!H75,""),IF(Просчет!I76='Смета в налоговую'!C46,Просчет!H76,""),IF(Просчет!I77='Смета в налоговую'!C46,Просчет!H77,"")) | C46: Брус сухой, нестроганый 50х50 мм | D46: =0.05*0.05*3*Просчет!B79 -> 0 | E46: м3 | F46: 13500 | G46: =F46/1.25*0.55 -> 5940 | H46: =(F46+G46)*D46 -> 0
B47: =_xlfn.TEXTJOIN(", ",,IF(Просчет!I56='Смета в налоговую'!C47,Просчет!H56,""),IF(Просчет!I57='Смета в налоговую'!C47,Просчет!H57,""),IF(Просчет!I58='Смета в налоговую'!C47,Просчет!H58,""),IF(Просчет!I59='Смета в налоговую'!C47,Просчет!H59,""),IF(Просчет!I60='Смета в налоговую'!C47,Просчет!H60,""),IF(Просчет!I61='Смета в налоговую'!C47,Просчет!H61,""),IF(Просчет!I62='Смета в налоговую'!C47,Просчет!H62,""),IF(Просчет!I63='Смета в налоговую'!C47,Просчет!H63,""),IF(Просчет!I64='Смета в налоговую'!C47,Просчет!H64,""),IF(Просчет!I65='Смета в налоговую'!C47,Просчет!H65,""),IF(Просчет!I66='Смета в налоговую'!C47,Просчет!H66,""),IF(Просчет!I67='Смета в налоговую'!C47,Просчет!H67,""),IF(Просчет!I68='Смета в налоговую'!C47,Просчет!H68,""),IF(Просчет!I69='Смета в налоговую'!C47,Просчет!H69,""),IF(Просчет!I70='Смета в налоговую'!C47,Просчет!H70,""),IF(Просчет!I71='Смета в налоговую'!C47,Просчет!H71,""),IF(Просчет!I72='Смета в налоговую'!C47,Просчет!H72,""),IF(Просчет!I73='Смета в налоговую'!C47,Просчет!H73,""),IF(Просчет!I74='Смета в налоговую'!C47,Просчет!H74,""),IF(Просчет!I75='Смета в налоговую'!C47,Просчет!H75,""),IF(Просчет!I76='Смета в налоговую'!C47,Просчет!H76,""),IF(Просчет!I77='Смета в налоговую'!C47,Просчет!H77,""),IF(Просчет!I78='Смета в налоговую'!C47,Просчет!H78,"")) | C47: Брус сухой, нестроганый 50х100 мм | D47: =0.05*0.1*6*(Просчет!B80+Просчет!B41) -> 0 | E47: м3 | F47: 13500 | G47: =F47/1.25*0.55 -> 5940 | H47: =(F47+G47)*D47 -> 0
...

Sheet Смета для клиента
A1: Приложение №3 к договору строительного подряда №00/00 от 00.00.2020 г.
A3: № | B3: Работа | C3: Материал | D3: Кол-во | E3: Ед. изм. | F3: Стоимость ед. материал | G3: Стоимость ед. работа | H3: Итого
A4: 1 | B4: Устройство фундамента
B5: ='Смета в налоговую'!B18 -> Устройство фундамента | C5: ='Смета в налоговую'!C18 -> 0 | D5: ='Смета в налоговую'!D18 -> 0 | E5: ='Смета в налоговую'!E18 -> компл. | F5: ='Смета в налоговую'!F18 -> 0 | G5: ='Смета в налоговую'!G18 -> 0 | H5: ='Смета в налоговую'!H18 -> 0
B6: ='Смета в налоговую'!B19 -> Устройство сетки от грызунов | C6: ='Смета в налоговую'!C19 -> Сетка от грызунов 1*10м | D6: ='Смета в налоговую'!D19 -> 0 | E6: ='Смета в налоговую'!E19 -> компл. | F6: ='Смета в налоговую'!F19 -> 219 | G6: ='Смета в налоговую'!G19 -> 96.36 | H6: ='Смета в налоговую'!H19 -> 0
B7: ='Смета в налоговую'!B20 -> Геология | C7: ='Смета в налоговую'!C20 -> 0 | D7: ='Смета в налоговую'!D20 -> 0 | E7: ='Смета в налоговую'!E20 -> компл. | F7: ='Смета в налоговую'!F20 -> 0 | G7: ='Смета в налоговую'!G20 -> 0 | H7: ='Смета в налоговую'!H20 -> 0
B8: ='Смета в налоговую'!B21 -> Устройство цоколя | C8: ='Смета в налоговую'!C21 -> Материал предоставляет Заказчик | D8: ='Смета в налоговую'!D21 -> 0 | E8: ='Смета в налоговую'!E21 -> компл. | F8: ='Смета в налоговую'!F21 -> 0 | G8: ='Смета в налоговую'!G21 -> 0 | H8: ='Смета в налоговую'!H21 -> 0
B9: ='Смета в налоговую'!B22 -> Устройство цоколя | C9: ='Смета в налоговую'!C22 -> HAUBERK ТЕХНОНИКОЛЬ Терракотовый кирпич | D9: ='Смета в налоговую'!D22 -> 0 | E9: ='Смета в налоговую'!E22 -> м2 | F9: ='Смета в налоговую'!F22 -> 0 | G9: ='Смета в налоговую'!G22 -> 0 | H9: ='Смета в налоговую'!H22 -> 0
A10: =A4+1 -> 2 | B10: Устройство каркаса и стропильной системы дома
B11: ='Смета в налоговую'!B24 | C11: ='Смета в налоговую'!C24 -> Брус 25х50 мм | D11: ='Смета в налоговую'!D24 -> 0 | E11: ='Смета в налоговую'!E24 -> м3 | F11: ='Смета в налоговую'!F24 -> 11500 | G11: ='Смета в налоговую'!G24 -> 5060 | H11: ='Смета в налоговую'!H24 -> 0
B12: ='Смета в налоговую'!B25 | C12: ='Смета в налоговую'!C25 -> Брус 25х100 мм | D12: ='Смета в налоговую'!D25 -> 0 | E12: ='Смета в налоговую'!E25 -> м3 | F12: ='Смета в налоговую'!F25 -> 11500 | G12: ='Смета в налоговую'!G25 -> 5060 | H12: ='Смета в налоговую'!H25 -> 0
